Workbook

Sheet Обложка
B2: Detention Navigator — юнит-экономика и 18-месячная модель
B4: Три сценария: пессимистичный / базовый / оптимистичный. Все вычисления — формулами Excel (изменяйте синие входы).
B6: Ключевые показатели (базовый сценарий)
B7: Цена Navigator Kit (разово) | C7: =Допущения!D5 -> 99
B8: Цена Status Monitor ($/мес) | C8: =Допущения!D6 -> 7.99
B9: Выручка на платного клиента (LTV) | C9: ='Юнит-экономика'!C16 -> 108.588
B10: CAC | C10: ='Юнит-экономика'!C17 -> 30
B11: LTV / CAC | C11: ='Юнит-экономика'!C18 -> 3.6196
B13: Состав файла
B14: Допущения | C14: Все входные параметры трёх сценариев (синие ячейки — редактируемые)
B15: Юнит-экономика | C15: LTV, CAC, маржа на клиента по сценариям
B16: Модель 18 мес | C16: Помесячный прогноз выручки и расходов по сценариям
B17: Источники | C17: Откуда взяты внешние данные
B19: Шрифты: синий — входы, чёрный — формулы, зелёный — ссылки на другие листы.

Sheet Допущения
B2: Допущения по сценариям
B4: Параметр | C4: Пессимистичный | D4: Базовый | E4: Оптимистичный | F4: Комментарий
B5: Цена Navigator Kit, $ (разово) | C5: 99 | D5: 99 | E5: 99 | F5: Из спецификации
B6: Цена Status Monitor, $/мес | C6: 7.99 | D6: 7.99 | E6: 7.99 | F6: Из спецификации
B7: Конверсия лендинг → покупка Kit | C7: 0.01 | D7: 0.025 | E7: 0.04 | F7: Гипотеза; пилот измерит
B8: Доля покупателей Kit, берущих Monitor | C8: 0.25 | D8: 0.4 | E8: 0.55 | F8: Кризисный сценарий повышает
B9: Средняя жизнь подписки Monitor, мес | C9: 2 | D9: 3 | E9: 4 | F9: Медиана детеншн-дела 36 дн. (EOIR)
B10: Посетителей лендинга в мес, старт | C10: 5000 | D10: 8000 | E10: 12000 | F10: SEO + общины
B11: Рост трафика, % в мес | C11: 0.05 | D11: 0.1 | E11: 0.15 | F11: Контент + сарафан
B12: CAC на платного клиента, $ | C12: 45 | D12: 30 | E12: 18 | F12: Общины дешевле рекламы
B13: Переменные расходы на клиента, $ | C13: 4 | D13: 3 | E13: 2.5 | F13: Stripe ~3%, хостинг, email
B14: Фикс. расходы в мес, $ (старт) | C14: 3000 | D14: 3000 | E14: 3000 | F14: Инфраструктура, контент, ревью адвоката
B15: Рост фикс. расходов, % в мес | C15: 0.02 | D15: 0.02 | E15: 0.02 | F15: Масштабирование контента

Sheet Юнит-экономика
B2: Юнит-экономика на платного клиента
B4: Показатель | C4: Пессимистичный | D4: Базовый | E4: Оптимистичный | F4: Формула
B5: Выручка Kit на клиента, $ | C5: =Допущения!C5 -> 99 | D5: =Допущения!D5 -> 99 | E5: =Допущения!E5 -> 99 | F5: цена Kit
B6: Выручка Monitor на клиента, $ | C6: =Допущения!C6*Допущения!C8*Допущения!C9 -> 3.995 | D6: =Допущения!D6*Допущения!D8*Допущения!D9 -> 9.588 | E6: =Допущения!E6*Допущения!E8*Допущения!E9 -> 17.578 | F6: цена × доля × мес
B7: Выручка всего (LTV), $ | C7: =C5+C6 -> 102.995 | D7: =D5+D6 -> 108.588 | E7: =E5+E6 -> 116.578 | F7: Kit + Monitor
B8: Переменные расходы, $ | C8: =Допущения!C13 -> 4 | D8: =Допущения!D13 -> 3 | E8: =Допущения!E13 -> 2.5 | F8: Stripe, инфра
B9: Валовая прибыль на клиента, $ | C9: =C7-C8 -> 98.995 | D9: =D7-D8 -> 105.588 | E9: =E7-E8 -> 114.078 | F9: LTV − переменные
B10: CAC, $ | C10: =Допущения!C12 -> 45 | D10: =Допущения!D12 -> 30 | E10: =Допущения!E12 -> 18 | F10: гипотеза
B11: LTV / CAC | C11: =C7/C10 -> 2.2887778 | D11: =D7/D10 -> 3.6196 | E11: =E7/E10 -> 6.4765556
B12: Чистая маржа на клиента, $ | C12: =C9-C10 -> 53.995 | D12: =D9-D10 -> 75.588 | E12: =E9-E10 -> 96.078 | F12: валовая − CAC
B15: Сводка для обложки (базовый сценарий)
B16: LTV | C16: =D7 -> 108.588
B17: CAC | C17: =D10 -> 30
B18: LTV / CAC | C18: =D11 -> 3.6196

Sheet Модель 18 мес
B2: Помесячная модель, 18 месяцев
B4: Сценарий: Пессимистичный
B5: Показатель | C5: М1 | D5: М2 | E5: М3 | F5: М4 | G5: М5 | H5: М6 | I5: М7 | J5: М8 | K5: М9 | L5: М10 | M5: М11 | N5: М12 | O5: М13 | P5: М14 | Q5: М15 | R5: М16 | S5: М17 | T5: М18
B6: Трафик (посетители) | C6: =Допущения!C10 -> 5000 | D6: =C6*(1+Допущения!C11) -> 5250 | E6: =D6*(1+Допущения!C11) -> 5512.5 | F6: =E6*(1+Допущения!C11) -> 5788.125 | G6: =F6*(1+Допущения!C11) -> 6077.5312 | H6: =G6*(1+Допущения!C11) -> 6381.4078 | I6: =H6*(1+Допущения!C11) -> 6700.4782 | J6: =I6*(1+Допущения!C11) -> 7035.5021 | K6: =J6*(1+Допущения!C11) -> 7387.2772 | L6: =K6*(1+Допущения!C11) -> 7756.6411 | M6: =L6*(1+Допущения!C11) -> 8144.4731 | N6: =M6*(1+Допущения!C11) -> 8551.6968 | O6: =N6*(1+Допущения!C11) -> 8979.2816 | P6: =O6*(1+Допущения!C11) -> 9428.2457 | Q6: =P6*(1+Допущения!C11) -> 9899.658 | R6: =Q6*(1+Допущения!C11) -> 10394.641 | S6: =R6*(1+Допущения!C11) -> 10914.373 | T6: =S6*(1+Допущения!C11) -> 11460.092
B7: Покупатели Kit | C7: =C6*Допущения!C7 -> 50 | D7: =D6*Допущения!C7 -> 52.5 | E7: =E6*Допущения!C7 -> 55.125 | F7: =F6*Допущения!C7 -> 57.88125 | G7: =G6*Допущения!C7 -> 60.775312 | H7: =H6*Допущения!C7 -> 63.814078 | I7: =I6*Допущения!C7 -> 67.004782 | J7: =J6*Допущения!C7 -> 70.355021 | K7: =K6*Допущения!C7 -> 73.872772 | L7: =L6*Допущения!C7 -> 77.566411 | M7: =M6*Допущения!C7 -> 81.444731 | N7: =N6*Допущения!C7 -> 85.516968 | O7: =O6*Допущения!C7 -> 89.792816 | P7: =P6*Допущения!C7 -> 94.282457 | Q7: =Q6*Допущения!C7 -> 98.99658 | R7: =R6*Допущения!C7 -> 103.94641 | S7: =S6*Допущения!C7 -> 109.14373 | T7: =T6*Допущения!C7 -> 114.60092
B8: Новые подписчики Monitor | C8: =C7*Допущения!C8 -> 12.5 | D8: =D7*Допущения!C8 -> 13.125 | E8: =E7*Допущения!C8 -> 13.78125 | F8: =F7*Допущения!C8 -> 14.470313 | G8: =G7*Допущения!C8 -> 15.193828 | H8: =H7*Допущения!C8 -> 15.95352 | I8: =I7*Допущения!C8 -> 16.751196 | J8: =J7*Допущения!C8 -> 17.588755 | K8: =K7*Допущения!C8 -> 18.468193 | L8: =L7*Допущения!C8 -> 19.391603 | M8: =M7*Допущения!C8 -> 20.361183 | N8: =N7*Допущения!C8 -> 21.379242 | O8: =O7*Допущения!C8 -> 22.448204 | P8: =P7*Допущения!C8 -> 23.570614 | Q8: =Q7*Допущения!C8 -> 24.749145 | R8: =R7*Допущения!C8 -> 25.986602 | S8: =S7*Допущения!C8 -> 27.285932 | T8: =T7*Допущения!C8 -> 28.650229
B9: Активные подписчики Monitor | C9: =SUM(OFFSET(C8,0,-MIN(0,Допущения!C9-1)):C8) -> 12.5 | D9: =SUM(OFFSET(D8,0,-MIN(1,Допущения!C9-1)):D8) -> 25.625 | E9: =SUM(OFFSET(E8,0,-MIN(2,Допущения!C9-1)):E8) -> 26.90625 | F9: =SUM(OFFSET(F8,0,-MIN(3,Допущения!C9-1)):F8) -> 28.251562 | G9: =SUM(OFFSET(G8,0,-MIN(4,Допущения!C9-1)):G8) -> 29.664141 | H9: =SUM(OFFSET(H8,0,-MIN(5,Допущения!C9-1)):H8) -> 31.147348 | I9: =SUM(OFFSET(I8,0,-MIN(6,Допущения!C9-1)):I8) -> 32.704715 | J9: =SUM(OFFSET(J8,0,-MIN(7,Допущения!C9-1)):J8) -> 34.339951 | K9: =SUM(OFFSET(K8,0,-MIN(8,Допущения!C9-1)):K8) -> 36.056948 | L9: =SUM(OFFSET(L8,0,-MIN(9,Допущения!C9-1)):L8) -> 37.859796 | M9: =SUM(OFFSET(M8,0,-MIN(10,Допущения!C9-1)):M8) -> 39.752786 | N9: =SUM(OFFSET(N8,0,-MIN(11,Допущения!C9-1)):N8) -> 41.740425 | O9: =SUM(OFFSET(O8,0,-MIN(12,Допущения!C9-1)):O8) -> 43.827446 | P9: =SUM(OFFSET(P8,0,-MIN(13,Допущения!C9-1)):P8) -> 46.018818 | Q9: =SUM(OFFSET(Q8,0,-MIN(14,Допущения!C9-1)):Q8) -> 48.319759 | R9: =SUM(OFFSET(R8,0,-MIN(15,Допущения!C9-1)):R8) -> 50.735747 | S9: =SUM(OFFSET(S8,0,-MIN(16,Допущения!C9-1)):S8) -> 53.272535 | T9: =SUM(OFFSET(T8,0,-MIN(17,Допущения!C9-1)):T8) -> 55.936161
B10: Выручка Kit, $ | C10: =C7*Допущения!C5 -> 4950 | D10: =D7*Допущения!C5 -> 5197.5 | E10: =E7*Допущения!C5 -> 5457.375 | F10: =F7*Допущения!C5 -> 5730.2437 | G10: =G7*Допущения!C5 -> 6016.7559 | H10: =H7*Допущения!C5 -> 6317.5937 | I10: =I7*Допущения!C5 -> 6633.4734 | J10: =J7*Допущения!C5 -> 6965.1471 | K10: =K7*Допущения!C5 -> 7313.4044 | L10: =L7*Допущения!C5 -> 7679.0747 | M10: =M7*Допущения!C5 -> 8063.0284 | N10: =N7*Допущения!C5 -> 8466.1798 | O10: =O7*Допущения!C5 -> 8889.4888 | P10: =P7*Допущения!C5 -> 9333.9633 | Q10: =Q7*Допущения!C5 -> 9800.6614 | R10: =R7*Допущения!C5 -> 10290.694 | S10: =S7*Допущения!C5 -> 10805.229 | T10: =T7*Допущения!C5 -> 11345.491
B11: Выручка Monitor, $ | C11: =C9*Допущения!C6 -> 99.875 | D11: =D9*Допущения!C6 -> 204.74375 | E11: =E9*Допущения!C6 -> 214.98094 | F11: =F9*Допущения!C6 -> 225.72998 | G11: =G9*Допущения!C6 -> 237.01648 | H11: =H9*Допущения!C6 -> 248.86731 | I11: =I9*Допущения!C6 -> 261.31067 | J11: =J9*Допущения!C6 -> 274.37621 | K11: =K9*Допущения!C6 -> 288.09502 | L11: =L9*Допущения!C6 -> 302.49977 | M11: =M9*Допущения!C6 -> 317.62476 | N11: =N9*Допущения!C6 -> 333.50599 | O11: =O9*Допущения!C6 -> 350.18129 | P11: =P9*Допущения!C6 -> 367.69036 | Q11: =Q9*Допущения!C6 -> 386.07488 | R11: =R9*Допущения!C6 -> 405.37862 | S11: =S9*Допущения!C6 -> 425.64755 | T11: =T9*Допущения!C6 -> 446.92993
B12: Выручка всего, $ | C12: =C10+C11 -> 5049.875 | D12: =D10+D11 -> 5402.2437 | E12: =E10+E11 -> 5672.3559 | F12: =F10+F11 -> 5955.9737 | G12: =G10+G11 -> 6253.7724 | H12: =H10+H11 -> 6566.461 | I12: =I10+I11 -> 6894.7841 | J12: =J10+J11 -> 7239.5233 | ... T12: =T10+T11 -> 11792.421
B13: Переменные расходы, $ | C13: =(C7+C9)*Допущения!C13 -> 250 | D13: =(D7+D9)*Допущения!C13 -> 312.5 | E13: =(E7+E9)*Допущения!C13 -> 328.125 | F13: =(F7+F9)*Допущения!C13 -> 344.53125 | G13: =(G7+G9)*Допущения!C13 -> 361.75781 | H13: =(H7+H9)*Допущения!C13 -> 379.8457 | I13: =(I7+I9)*Допущения!C13 -> 398.83799 | J13: =(J7+J9)*Допущения!C13 -> 418.77989 | K13: =(K7+K9)*Допущения!C13 -> 439.71888 | L13: =(L7+L9)*Допущения!C13 -> 461.70483 | M13: =(M7+M9)*Допущения!C13 -> 484.79007 | N13: =(N7+N9)*Допущения!C13 -> 509.02957 | O13: =(O7+O9)*Допущения!C13 -> 534.48105 | P13: =(P7+P9)*Допущения!C13 -> 561.2051 | Q13: =(Q7+Q9)*Допущения!C13 -> 589.26536 | R13: =(R7+R9)*Допущения!C13 -> 618.72862 | S13: =(S7+S9)*Допущения!C13 -> 649.66506 | T13: =(T7+T9)*Допущения!C13 -> 682.14831
B14: Маркетинг (CAC), $ | C14: =C7*Допущения!C12 -> 2250 | D14: =D7*Допущения!C12 -> 2362.5 | E14: =E7*Допущения!C12 -> 2480.625 | F14: =F7*Допущения!C12 -> 2604.6562 | G14: =G7*Допущения!C12 -> 2734.8891 | H14: =H7*Допущения!C12 -> 2871.6335 | I14: =I7*Допущения!C12 -> 3015.2152 | J14: =J7*Допущения!C12 -> 3165.976 | K14: =K7*Допущения!C12 -> 3324.2747 | L14: =L7*Допущения!C12 -> 3490.4885 | M14: =M7*Допущения!C12 -> 3665.0129 | N14: =N7*Допущения!C12 -> 3848.2636 | O14: =O7*Допущения!C12 -> 4040.6767 | P14: =P7*Допущения!C12 -> 4242.7106 | Q14: =Q7*Допущения!C12 -> 4454.8461 | R14: =R7*Допущения!C12 -> 4677.5884 | S14: =S7*Допущения!C12 -> 4911.4678 | T14: =T7*Допущения!C12 -> 5157.0412
B15: Фиксированные расходы, $ | C15: =Допущения!C14 -> 3000 | D15: =C15*(1+Допущения!C15) -> 3060 | E15: =D15*(1+Допущения!C15) -> 3121.2 | F15: =E15*(1+Допущения!C15) -> 3183.624 | G15: =F15*(1+Допущения!C15) -> 3247.2965 | H15: =G15*(1+Допущения!C15) -> 3312.2424 | I15: =H15*(1+Допущения!C15) -> 3378.4873 | J15: =I15*(1+Допущения!C15) -> 3446.057 | K15: =J15*(1+Допущения!C15) -> 3514.9781 | L15: =K15*(1+Допущения!C15) -> 3585.2777 | M15: =L15*(1+Допущения!C15) -> 3656.9833 | N15: =M15*(1+Допущения!C15) -> 3730.1229 | O15: =N15*(1+Допущения!C15) -> 3804.7254 | P15: =O15*(1+Допущения!C15) -> 3880.8199 | Q15: =P15*(1+Допущения!C15) -> 3958.4363 | R15: =Q15*(1+Допущения!C15) -> 4037.605 | S15: =R15*(1+Допущения!C15) -> 4118.3571 | T15: =S15*(1+Допущения!C15) -> 4200.7243
B16: Чистый денежный поток, $ | C16: =C12-C13-C14-C15 -> -450.125 | D16: =D12-D13-D14-D15 -> -332.75625 | E16: =E12-E13-E14-E15 -> -257.59406 | F16: =F12-F13-F14-F15 -> -176.83777 | G16: =G12-G13-G14-G15 -> -90.170934 | H16: =H12-H13-H14-H15 -> 2.7394138 | I16: =I12-I13-I14-I15 -> 102.24366 | J16: =J12-J13-J14-J15 -> 208.71046 | ... T16: =T12-T13-T14-T15 -> 1752.5068
B17: Накопленный поток, $ | C17: =C16 -> -450.125 | D17: =C17+D16 -> -782.88125 | E17: =D17+E16 -> -1040.4753 | F17: =E17+F16 -> -1217.3131 | G17: =F17+G16 -> -1307.484 | H17: =G17+H16 -> -1304.7446 | I17: =H17+I16 -> -1202.5009 | J17: =I17+J16 -> -993.79048 | K17: =J17+K16 -> -671.26279 | ... T17: =S17+T16 -> 8785.9155
B20: Сценарий: Базовый
B21: Показатель | C21: М1 | D21: М2 | E21: М3 | F21: М4 | G21: М5 | H21: М6 | I21: М7 | J21: М8 | K21: М9 | L21: М10 | M21: М11 | N21: М12 | O21: М13 | P21: М14 | Q21: М15 | R21: М16 | S21: М17 | T21: М18
B22: Трафик (посетители) | C22: =Допущения!D10 -> 8000 | D22: =C22*(1+Допущения!D11) -> 8800 | E22: =D22*(1+Допущения!D11) -> 9680 | F22: =E22*(1+Допущения!D11) -> 10648 | G22: =F22*(1+Допущения!D11) -> 11712.8 | H22: =G22*(1+Допущения!D11) -> 12884.08 | I22: =H22*(1+Допущения!D11) -> 14172.488 | J22: =I22*(1+Допущения!D11) -> 15589.737 | K22: =J22*(1+Допущения!D11) -> 17148.71 | L22: =K22*(1+Допущения!D11) -> 18863.582 | M22: =L22*(1+Допущения!D11) -> 20749.94 | N22: =M22*(1+Допущения!D11) -> 22824.934 | O22: =N22*(1+Допущения!D11) -> 25107.427 | P22: =O22*(1+Допущения!D11) -> 27618.17 | Q22: =P22*(1+Допущения!D11) -> 30379.987 | R22: =Q22*(1+Допущения!D11) -> 33417.985 | S22: =R22*(1+Допущения!D11) -> 36759.784 | T22: =S22*(1+Допущения!D11) -> 40435.762
B23: Покупатели Kit | C23: =C22*Допущения!D7 -> 200 | D23: =D22*Допущения!D7 -> 220 | E23: =E22*Допущения!D7 -> 242 | F23: =F22*Допущения!D7 -> 266.2 | G23: =G22*Допущения!D7 -> 292.82 | H23: =H22*Допущения!D7 -> 322.102 | I23: =I22*Допущения!D7 -> 354.3122 | J23: =J22*Допущения!D7 -> 389.74342 | K23: =K22*Допущения!D7 -> 428.71776 | L23: =L22*Допущения!D7 -> 471.58954 | M23: =M22*Допущения!D7 -> 518.74849 | N23: =N22*Допущения!D7 -> 570.62334 | O23: =O22*Допущения!D7 -> 627.68568 | P23: =P22*Допущения!D7 -> 690.45424 | Q23: =Q22*Допущения!D7 -> 759.49967 | R23: =R22*Допущения!D7 -> 835.44963 | S23: =S22*Допущения!D7 -> 918.9946 | T23: =T22*Допущения!D7 -> 1010.8941
B24: Новые подписчики Monitor | C24: =C23*Допущения!D8 -> 80 | D24: =D23*Допущения!D8 -> 88 | E24: =E23*Допущения!D8 -> 96.8 | F24: =F23*Допущения!D8 -> 106.48 | G24: =G23*Допущения!D8 -> 117.128 | H24: =H23*Допущения!D8 -> 128.8408 | I24: =I23*Допущения!D8 -> 141.72488 | J24: =J23*Допущения!D8 -> 155.89737 | K24: =K23*Допущения!D8 -> 171.4871 | L24: =L23*Допущения!D8 -> 188.63582 | M24: =M23*Допущения!D8 -> 207.4994 | N24: =N23*Допущения!D8 -> 228.24934 | O24: =O23*Допущения!D8 -> 251.07427 | P24: =P23*Допущения!D8 -> 276.1817 | Q24: =Q23*Допущения!D8 -> 303.79987 | R24: =R23*Допущения!D8 -> 334.17985 | S24: =S23*Допущения!D8 -> 367.59784 | T24: =T23*Допущения!D8 -> 404.35762
B25: Активные подписчики Monitor | C25: =SUM(OFFSET(C24,0,-MIN(0,Допущения!D9-1)):C24) -> 80 | D25: =SUM(OFFSET(D24,0,-MIN(1,Допущения!D9-1)):D24) -> 168 | E25: =SUM(OFFSET(E24,0,-MIN(2,Допущения!D9-1)):E24) -> 264.8 | F25: =SUM(OFFSET(F24,0,-MIN(3,Допущения!D9-1)):F24) -> 291.28 | G25: =SUM(OFFSET(G24,0,-MIN(4,Допущения!D9-1)):G24) -> 320.408 | H25: =SUM(OFFSET(H24,0,-MIN(5,Допущения!D9-1)):H24) -> 352.4488 | I25: =SUM(OFFSET(I24,0,-MIN(6,Допущения!D9-1)):I24) -> 387.69368 | J25: =SUM(OFFSET(J24,0,-MIN(7,Допущения!D9-1)):J24) -> 426.46305 | K25: =SUM(OFFSET(K24,0,-MIN(8,Допущения!D9-1)):K24) -> 469.10935 | L25: =SUM(OFFSET(L24,0,-MIN(9,Допущения!D9-1)):L24) -> 516.02029 | M25: =SUM(OFFSET(M24,0,-MIN(10,Допущения!D9-1)):M24) -> 567.62232 | N25: =SUM(OFFSET(N24,0,-MIN(11,Допущения!D9-1)):N24) -> 624.38455 | O25: =SUM(OFFSET(O24,0,-MIN(12,Допущения!D9-1)):O24) -> 686.823 | P25: =SUM(OFFSET(P24,0,-MIN(13,Допущения!D9-1)):P24) -> 755.5053 | Q25: =SUM(OFFSET(Q24,0,-MIN(14,Допущения!D9-1)):Q24) -> 831.05583 | R25: =SUM(OFFSET(R24,0,-MIN(15,Допущения!D9-1)):R24) -> 914.16142 | S25: =SUM(OFFSET(S24,0,-MIN(16,Допущения!D9-1)):S24) -> 1005.5776 | T25: =SUM(OFFSET(T24,0,-MIN(17,Допущения!D9-1)):T24) -> 1106.1353
B26: Выручка Kit, $ | C26: =C23*Допущения!D5 -> 19800 | D26: =D23*Допущения!D5 -> 21780 | E26: =E23*Допущения!D5 -> 23958 | F26: =F23*Допущения!D5 -> 26353.8 | G26: =G23*Допущения!D5 -> 28989.18 | H26: =H23*Допущения!D5 -> 31888.098 | I26: =I23*Допущения!D5 -> 35076.908 | J26: =J23*Допущения!D5 -> 38584.599 | K26: =K23*Допущения!D5 -> 42443.058 | L26: =L23*Допущения!D5 -> 46687.364 | M26: =M23*Допущения!D5 -> 51356.101 | N26: =N23*Допущения!D5 -> 56491.711 | O26: =O23*Допущения!D5 -> 62140.882 | P26: =P23*Допущения!D5 -> 68354.97 | Q26: =Q23*Допущения!D5 -> 75190.467 | R26: =R23*Допущения!D5 -> 82709.514 | S26: =S23*Допущения!D5 -> 90980.465 | T26: =T23*Допущения!D5 -> 100078.51
B27: Выручка Monitor, $ | C27: =C25*Допущения!D6 -> 639.2 | D27: =D25*Допущения!D6 -> 1342.32 | E27: =E25*Допущения!D6 -> 2115.752 | F27: =F25*Допущения!D6 -> 2327.3272 | G27: =G25*Допущения!D6 -> 2560.0599 | H27: =H25*Допущения!D6 -> 2816.0659 | I27: =I25*Допущения!D6 -> 3097.6725 | J27: =J25*Допущения!D6 -> 3407.4398 | K27: =K25*Допущения!D6 -> 3748.1837 | L27: =L25*Допущения!D6 -> 4123.0021 | M27: =M25*Допущения!D6 -> 4535.3023 | N27: =N25*Допущения!D6 -> 4988.8325 | O27: =O25*Допущения!D6 -> 5487.7158 | P27: =P25*Допущения!D6 -> 6036.4874 | Q27: =Q25*Допущения!D6 -> 6640.1361 | R27: =R25*Допущения!D6 -> 7304.1497 | S27: =S25*Допущения!D6 -> 8034.5647 | T27: =T25*Допущения!D6 -> 8838.0212
B28: Выручка всего, $ | C28: =C26+C27 -> 20439.2 | D28: =D26+D27 -> 23122.32 | E28: =E26+E27 -> 26073.752 | F28: =F26+F27 -> 28681.127 | G28: =G26+G27 -> 31549.24 | H28: =H26+H27 -> 34704.164 | I28: =I26+I27 -> 38174.58 | J28: =J26+J27 -> 41992.038 | ... T28: =T26+T27 -> 108916.53
B29: Переменные расходы, $ | C29: =(C23+C25)*Допущения!D13 -> 840 | D29: =(D23+D25)*Допущения!D13 -> 1164 | E29: =(E23+E25)*Допущения!D13 -> 1520.4 | F29: =(F23+F25)*Допущения!D13 -> 1672.44 | G29: =(G23+G25)*Допущения!D13 -> 1839.684 | H29: =(H23+H25)*Допущения!D13 -> 2023.6524 | I29: =(I23+I25)*Допущения!D13 -> 2226.0176 | J29: =(J23+J25)*Допущения!D13 -> 2448.6194 | K29: =(K23+K25)*Допущения!D13 -> 2693.4813 | L29: =(L23+L25)*Допущения!D13 -> 2962.8295 | M29: =(M23+M25)*Допущения!D13 -> 3259.1124 | N29: =(N23+N25)*Допущения!D13 -> 3585.0237 | O29: =(O23+O25)*Допущения!D13 -> 3943.526 | P29: =(P23+P25)*Допущения!D13 -> 4337.8786 | Q29: =(Q23+Q25)*Допущения!D13 -> 4771.6665 | R29: =(R23+R25)*Допущения!D13 -> 5248.8332 | S29: =(S23+S25)*Допущения!D13 -> 5773.7165 | T29: =(T23+T25)*Допущения!D13 -> 6351.0881
B30: Маркетинг (CAC), $ | C30: =C23*Допущения!D12 -> 6000 | D30: =D23*Допущения!D12 -> 6600 | E30: =E23*Допущения!D12 -> 7260 | F30: =F23*Допущения!D12 -> 7986 | G30: =G23*Допущения!D12 -> 8784.6 | H30: =H23*Допущения!D12 -> 9663.06 | I30: =I23*Допущения!D12 -> 10629.366 | J30: =J23*Допущения!D12 -> 11692.303 | K30: =K23*Допущения!D12 -> 12861.533 | L30: =L23*Допущения!D12 -> 14147.686 | M30: =M23*Допущения!D12 -> 15562.455 | N30: =N23*Допущения!D12 -> 17118.7 | O30: =O23*Допущения!D12 -> 18830.57 | P30: =P23*Допущения!D12 -> 20713.627 | Q30: =Q23*Допущения!D12 -> 22784.99 | R30: =R23*Допущения!D12 -> 25063.489 | S30: =S23*Допущения!D12 -> 27569.838 | T30: =T23*Допущения!D12 -> 30326.822
B31: Фиксированные расходы, $ | C31: =Допущения!D14 -> 3000 | D31: =C31*(1+Допущения!D15) -> 3060 | E31: =D31*(1+Допущения!D15) -> 3121.2 | F31: =E31*(1+Допущения!D15) -> 3183.624 | G31: =F31*(1+Допущения!D15) -> 3247.2965 | H31: =G31*(1+Допущения!D15) -> 3312.2424 | I31: =H31*(1+Допущения!D15) -> 3378.4873 | J31: =I31*(1+Допущения!D15) -> 3446.057 | K31: =J31*(1+Допущения!D15) -> 3514.9781 | L31: =K31*(1+Допущения!D15) -> 3585.2777 | M31: =L31*(1+Допущения!D15) -> 3656.9833 | N31: =M31*(1+Допущения!D15) -> 3730.1229 | O31: =N31*(1+Допущения!D15) -> 3804.7254 | P31: =O31*(1+Допущения!D15) -> 3880.8199 | Q31: =P31*(1+Допущения!D15) -> 3958.4363 | R31: =Q31*(1+Допущения!D15) -> 4037.605 | S31: =R31*(1+Допущения!D15) -> 4118.3571 | T31: =S31*(1+Допущения!D15) -> 4200.7243
B32: Чистый денежный поток, $ | C32: =C28-C29-C30-C31 -> 10599.2 | D32: =D28-D29-D30-D31 -> 12298.32 | E32: =E28-E29-E30-E31 -> 14172.152 | F32: =F28-F29-F30-F31 -> 15839.063 | G32: =G28-G29-G30-G31 -> 17677.659 | H32: =H28-H29-H30-H31 -> 19705.209 | I32: =I28-I29-I30-I31 -> 21940.709 | J32: =J28-J29-J30-J31 -> 24405.059 | ... T32: =T28-T29-T30-T31 -> 68037.899
B33: Накопленный поток, $ | C33: =C32 -> 10599.2 | D33: =C33+D32 -> 22897.52 | E33: =D33+E32 -> 37069.672 | F33: =E33+F32 -> 52908.735 | G33: =F33+G32 -> 70586.395 | H33: =G33+H32 -> 90291.604 | I33: =H33+I32 -> 112232.31 | J33: =I33+J32 -> 136637.37 | K33: =J33+K32 -> 163758.62 | ... T33: =S33+T32 -> 586411.92
B36: Сценарий: Оптимистичный
B37: Показатель | C37: М1 | D37: М2 | E37: М3 | F37: М4 | G37: М5 | H37: М6 | I37: М7 | J37: М8 | K37: М9 | L37: М10 | M37: М11 | N37: М12 | O37: М13 | P37: М14 | Q37: М15 | R37: М16 | S37: М17 | T37: М18
B38: Трафик (посетители) | C38: =Допущения!E10 -> 12000 | D38: =C38*(1+Допущения!E11) -> 13800 | E38: =D38*(1+Допущения!E11) -> 15870 | F38: =E38*(1+Допущения!E11) -> 18250.5 | G38: =F38*(1+Допущения!E11) -> 20988.075 | H38: =G38*(1+Допущения!E11) -> 24136.286 | I38: =H38*(1+Допущения!E11) -> 27756.729 | J38: =I38*(1+Допущения!E11) -> 31920.239 | K38: =J38*(1+Допущения!E11) -> 36708.274 | L38: =K38*(1+Допущения!E11) -> 42214.516 | M38: =L38*(1+Допущения!E11) -> 48546.693 | N38: =M38*(1+Допущения!E11) -> 55828.697 | O38: =N38*(1+Допущения!E11) -> 64203.001 | P38: =O38*(1+Допущения!E11) -> 73833.451 | Q38: =P38*(1+Допущения!E11) -> 84908.469 | R38: =Q38*(1+Допущения!E11) -> 97644.74 | S38: =R38*(1+Допущения!E11) -> 112291.45 | T38: =S38*(1+Допущения!E11) -> 129135.17
B39: Покупатели Kit | C39: =C38*Допущения!E7 -> 480 | D39: =D38*Допущения!E7 -> 552 | E39: =E38*Допущения!E7 -> 634.8 | F39: =F38*Допущения!E7 -> 730.02 | G39: =G38*Допущения!E7 -> 839.523 | H39: =H38*Допущения!E7 -> 965.45145 | I39: =I38*Допущения!E7 -> 1110.2692 | J39: =J38*Допущения!E7 -> 1276.8095 | K39: =K38*Допущения!E7 -> 1468.331 | L39: =L38*Допущения!E7 -> 1688.5806 | M39: =M38*Допущения!E7 -> 1941.8677 | N39: =N38*Допущения!E7 -> 2233.1479 | O39: =O38*Допущения!E7 -> 2568.1201 | P39: =P38*Допущения!E7 -> 2953.3381 | Q39: =Q38*Допущения!E7 -> 3396.3388 | R39: =R38*Допущения!E7 -> 3905.7896 | S39: =S38*Допущения!E7 -> 4491.658 | T39: =T38*Допущения!E7 -> 5165.4067
B40: Новые подписчики Monitor | C40: =C39*Допущения!E8 -> 264 | D40: =D39*Допущения!E8 -> 303.6 | E40: =E39*Допущения!E8 -> 349.14 | F40: =F39*Допущения!E8 -> 401.511 | G40: =G39*Допущения!E8 -> 461.73765 | H40: =H39*Допущения!E8 -> 530.9983 | I40: =I39*Допущения!E8 -> 610.64804 | J40: =J39*Допущения!E8 -> 702.24525 | K40: =K39*Допущения!E8 -> 807.58204 | L40: =L39*Допущения!E8 -> 928.71934 | M40: =M39*Допущения!E8 -> 1068.0272 | N40: =N39*Допущения!E8 -> 1228.2313 | O40: =O39*Допущения!E8 -> 1412.466 | P40: =P39*Допущения!E8 -> 1624.3359 | Q40: =Q39*Допущения!E8 -> 1867.9863 | R40: =R39*Допущения!E8 -> 2148.1843 | S40: =S39*Допущения!E8 -> 2470.4119 | T40: =T39*Допущения!E8 -> 2840.9737
B41: Активные подписчики Monitor | C41: =SUM(OFFSET(C40,0,-MIN(0,Допущения!E9-1)):C40) -> 264 | D41: =SUM(OFFSET(D40,0,-MIN(1,Допущения!E9-1)):D40) -> 567.6 | E41: =SUM(OFFSET(E40,0,-MIN(2,Допущения!E9-1)):E40) -> 916.74 | F41: =SUM(OFFSET(F40,0,-MIN(3,Допущения!E9-1)):F40) -> 1318.251 | G41: =SUM(OFFSET(G40,0,-MIN(4,Допущения!E9-1)):G40) -> 1515.9887 | H41: =SUM(OFFSET(H40,0,-MIN(5,Допущения!E9-1)):H40) -> 1743.3869 | I41: =SUM(OFFSET(I40,0,-MIN(6,Допущения!E9-1)):I40) -> 2004.895 | J41: =SUM(OFFSET(J40,0,-MIN(7,Допущения!E9-1)):J40) -> 2305.6292 | K41: =SUM(OFFSET(K40,0,-MIN(8,Допущения!E9-1)):K40) -> 2651.4736 | L41: =SUM(OFFSET(L40,0,-MIN(9,Допущения!E9-1)):L40) -> 3049.1947 | M41: =SUM(OFFSET(M40,0,-MIN(10,Допущения!E9-1)):M40) -> 3506.5739 | N41: =SUM(OFFSET(N40,0,-MIN(11,Допущения!E9-1)):N40) -> 4032.5599 | O41: =SUM(OFFSET(O40,0,-MIN(12,Допущения!E9-1)):O40) -> 4637.4439 | P41: =SUM(OFFSET(P40,0,-MIN(13,Допущения!E9-1)):P40) -> 5333.0605 | Q41: =SUM(OFFSET(Q40,0,-MIN(14,Допущения!E9-1)):Q40) -> 6133.0196 | R41: =SUM(OFFSET(R40,0,-MIN(15,Допущения!E9-1)):R40) -> 7052.9726 | S41: =SUM(OFFSET(S40,0,-MIN(16,Допущения!E9-1)):S40) -> 8110.9184 | T41: =SUM(OFFSET(T40,0,-MIN(17,Допущения!E9-1)):T40) -> 9327.5562
B42: Выручка Kit, $ | C42: =C39*Допущения!E5 -> 47520 | D42: =D39*Допущения!E5 -> 54648 | E42: =E39*Допущения!E5 -> 62845.2 | F42: =F39*Допущения!E5 -> 72271.98 | G42: =G39*Допущения!E5 -> 83112.777 | H42: =H39*Допущения!E5 -> 95579.694 | I42: =I39*Допущения!E5 -> 109916.65 | J42: =J39*Допущения!E5 -> 126404.14 | K42: =K39*Допущения!E5 -> 145364.77 | L42: =L39*Допущения!E5 -> 167169.48 | M42: =M39*Допущения!E5 -> 192244.9 | N42: =N39*Допущения!E5 -> 221081.64 | O42: =O39*Допущения!E5 -> 254243.89 | P42: =P39*Допущения!E5 -> 292380.47 | Q42: =Q39*Допущения!E5 -> 336237.54 | R42: =R39*Допущения!E5 -> 386673.17 | S42: =S39*Допущения!E5 -> 444674.14 | T42: =T39*Допущения!E5 -> 511375.27
B43: Выручка Monitor, $ | C43: =C41*Допущения!E6 -> 2109.36 | D43: =D41*Допущения!E6 -> 4535.124 | E43: =E41*Допущения!E6 -> 7324.7526 | F43: =F41*Допущения!E6 -> 10532.825 | G43: =G41*Допущения!E6 -> 12112.749 | H43: =H41*Допущения!E6 -> 13929.662 | I43: =I41*Допущения!E6 -> 16019.111 | J43: =J41*Допущения!E6 -> 18421.978 | K43: =K41*Допущения!E6 -> 21185.274 | L43: =L41*Допущения!E6 -> 24363.065 | M43: =M41*Допущения!E6 -> 28017.525 | N43: =N41*Допущения!E6 -> 32220.154 | O43: =O41*Допущения!E6 -> 37053.177 | P43: =P41*Допущения!E6 -> 42611.154 | Q43: =Q41*Допущения!E6 -> 49002.827 | R43: =R41*Допущения!E6 -> 56353.251 | S43: =S41*Допущения!E6 -> 64806.238 | T43: =T41*Допущения!E6 -> 74527.174
B44: Выручка всего, $ | C44: =C42+C43 -> 49629.36 | D44: =D42+D43 -> 59183.124 | E44: =E42+E43 -> 70169.953 | F44: =F42+F43 -> 82804.805 | G44: =G42+G43 -> 95225.526 | H44: =H42+H43 -> 109509.36 | I44: =I42+I43 -> 125935.76 | J44: =J42+J43 -> 144826.12 | ... T44: =T42+T43 -> 585902.44
B45: Переменные расходы, $ | C45: =(C39+C41)*Допущения!E13 -> 1860 | D45: =(D39+D41)*Допущения!E13 -> 2799 | E45: =(E39+E41)*Допущения!E13 -> 3878.85 | F45: =(F39+F41)*Допущения!E13 -> 5120.6775 | G45: =(G39+G41)*Допущения!E13 -> 5888.7791 | H45: =(H39+H41)*Допущения!E13 -> 6772.096 | I45: =(I39+I41)*Допущения!E13 -> 7787.9104 | J45: =(J39+J41)*Допущения!E13 -> 8956.097 | K45: =(K39+K41)*Допущения!E13 -> 10299.511 | L45: =(L39+L41)*Допущения!E13 -> 11844.438 | M45: =(M39+M41)*Допущения!E13 -> 13621.104 | N45: =(N39+N41)*Допущения!E13 -> 15664.27 | O45: =(O39+O41)*Допущения!E13 -> 18013.91 | P45: =(P39+P41)*Допущения!E13 -> 20715.996 | Q45: =(Q39+Q41)*Допущения!E13 -> 23823.396 | R45: =(R39+R41)*Допущения!E13 -> 27396.905 | S45: =(S39+S41)*Допущения!E13 -> 31506.441 | T45: =(T39+T41)*Допущения!E13 -> 36232.407
B46: Маркетинг (CAC), $ | C46: =C39*Допущения!E12 -> 8640 | D46: =D39*Допущения!E12 -> 9936 | E46: =E39*Допущения!E12 -> 11426.4 | F46: =F39*Допущения!E12 -> 13140.36 | G46: =G39*Допущения!E12 -> 15111.414 | H46: =H39*Допущения!E12 -> 17378.126 | I46: =I39*Допущения!E12 -> 19984.845 | J46: =J39*Допущения!E12 -> 22982.572 | K46: =K39*Допущения!E12 -> 26429.958 | L46: =L39*Допущения!E12 -> 30394.451 | M46: =M39*Допущения!E12 -> 34953.619 | N46: =N39*Допущения!E12 -> 40196.662 | O46: =O39*Допущения!E12 -> 46226.161 | P46: =P39*Допущения!E12 -> 53160.085 | Q46: =Q39*Допущения!E12 -> 61134.098 | R46: =R39*Допущения!E12 -> 70304.212 | S46: =S39*Допущения!E12 -> 80849.844 | T46: =T39*Допущения!E12 -> 92977.321
...

Sheet Источники
B2: Внешние данные и источники
B4: Данные | C4: Где использованы | D4: Source Name | E4: Source URL
B5: Медиана детеншн-дела 36 дней; жизнь подписки | C5: Допущения: жизнь Monitor | D5: Deportation Data Project — EOIR cases (CC0) | E5: https://github.com/deportationdata/eoir
B6: ~120 тыс. дел с задержанием в год (2025) | C6: Обоснование рынка | D6: Deportation Data Project — EOIR cases (CC0) | E6: https://github.com/deportationdata/eoir
B7: Языки задержанных 2025 (русский — 1 074, испанский — 113 386) | C7: Обоснование локализации | D7: Deportation Data Project — EOIR cases (CC0) | E7: https://github.com/deportationdata/eoir
B8: 19,7% задержанных на всё время дела имели адвоката | C8: Питч, FAQ | D8: Deportation Data Project — EOIR cases (CC0) | E8: https://github.com/deportationdata/eoir
B9: Цены $99 / $7,99 | C9: Допущения | D9: Спецификация продукта (внутр.) | E9: —
B10: Конверсии, CAC, расходы | C10: Допущения | D10: Гипотезы команды; подлежат измерению в пилоте | E10: —
